
Epoch 1/5


599/600 [============================>.] - ETA: 0s - loss: 0.0397
Traceback (most recent call last):
  File "C:\Users\motom\Desktop\Python\Sputnik_VAE\test2.py", line 103, in <module>
    cvae.fit([x_train, y_train_cat, y_train_cat], x_train, epochs=epoch_num, batch_size=batch_size, shuffle=True,   callbacks=[
  File "C:\Users\motom\Desktop\Python\Sputnik_VAE\venv\lib\site-packages\keras\src\utils\traceback_utils.py", line 70, in error_handler
    raise e.with_traceback(filtered_tb) from None
  File "C:\Users\motom\Desktop\Python\Sputnik_VAE\venv\lib\site-packages\wandb\integration\keras\callbacks\model_checkpoint.py", line 145, in on_epoch_end
    if self.is_old_tf_keras_version:
  File "C:\Users\motom\Desktop\Python\Sputnik_VAE\venv\lib\site-packages\wandb\integration\keras\callbacks\model_checkpoint.py", line 200, in is_old_tf_keras_version
    if parse_version(tf.keras.__version__) < parse_version("2.6.0"):
AttributeError: module 'keras.api._v2.keras' has no attribute '__version__'